<?xml version="1.0" ?>
<!-- =================================================================================== -->
<!-- |    This document was autogenerated by xacro from bob3.xacro                     | -->
<!-- |    EDITING THIS FILE BY HAND IS NOT RECOMMENDED                                 | -->
<!-- =================================================================================== -->
<robot name="cobo">
  <material name="black">
    <color rgba="0.0 0.0 0.0 1.0"/>
  </material>
  <material name="blue">
    <color rgba="0.0 0.0 0.8 1.0"/>
  </material>
  <material name="green">
    <color rgba="0.0 1.0 0.0 1.0"/>
  </material>
  <material name="grey">
    <color rgba="0.2 0.2 0.2 1.0"/>
  </material>
  <material name="orange">
    <color rgba="1.0 0.4235294117647059 0.0392156862745098 1.0"/>
  </material>
  <material name="brown">
    <color rgba="0.8705882352941177 0.8117647058823529 0.7647058823529411 1.0"/>
  </material>
  <material name="red">
    <color rgba="0.8 0.0 0.0 1.0"/>
  </material>
  <material name="white">
    <color rgba="1.0 1.0 1.0 1.0"/>
  </material>
  <!-- Space btw top of beam and the each joint -->
  <link name="base_link">
    <visual>
      <origin rpy="0 0 0" xyz="0 0 0"/>
      <geometry>
        <box size="0.43 0.51 0.51"/>
      </geometry>
      <material name="blue"/>
    </visual>
  </link>
  <!-- left wheel Link -->
  <link name="left_wheel">
    <collision>
      <origin rpy="1.5707963267948966 0 0" xyz="0 0 0"/>
      <geometry>
        <cylinder length="0.02" radius="0.072"/>
      </geometry>
    </collision>
    <visual>
      <origin rpy="1.5707963267948966 0 0" xyz="0 0 0"/>
      <geometry>
        <cylinder length="0.02" radius="0.072"/>
      </geometry>
      <material name="black"/>
    </visual>
    <inertial>
      <origin rpy="1.5707963267948966 0 0" xyz="0 0 0"/>
      <mass value="0.3"/>
      <inertia ixx="0.005409999999999999" ixy="0.0" ixz="0.0" iyy="0.00012959999999999998" iyz="0.0" izz="0.00012959999999999998"/>
    </inertial>
  </link>
  <joint name="left_wheel_joint" type="continuous">
    <parent link="base_link"/>
    <child link="left_wheel"/>
    <origin rpy="0 0 0" xyz="0 0.255 -0.255"/>
    <axis xyz="0 1 0"/>
    <dynamics damping="0.2"/>
  </joint>
  <joint name="right_wheel_joint" type="continuous">
    <parent link="base_link"/>
    <child link="right_wheel"/>
    <origin rpy="0 0 0" xyz="0 -0.255 -0.255"/>
    <axis xyz="0 1 0"/>
    <dynamics damping="0.2"/>
  </joint>
  <!-- right wheel Link -->
  <link name="right_wheel">
    <collision>
      <origin rpy="1.5707963267948966 0 0" xyz="0 0 0"/>
      <geometry>
        <cylinder length="0.02" radius="0.072"/>
      </geometry>
    </collision>
    <visual>
      <origin rpy="1.5707963267948966 0 0" xyz="0 0 0"/>
      <geometry>
        <cylinder length="0.02" radius="0.072"/>
      </geometry>
      <material name="black"/>
    </visual>
    <inertial>
      <origin rpy="1.5707963267948966 0 0" xyz="0 0 0"/>
      <mass value="0.3"/>
      <inertia ixx="0.005409999999999999" ixy="0.0" ixz="0.0" iyy="0.00012959999999999998" iyz="0.0" izz="0.00012959999999999998"/>
    </inertial>
  </link>
  <joint name="caster_frontal_wheel_joint" type="fixed">
    <parent link="base_link"/>
    <child link="caster_frontal_wheel"/>
    <origin rpy="0 0 0" xyz="0.219 0 -0.255"/>
  </joint>
  <!-- caster frontal wheel Link -->
  <link name="caster_frontal_wheel">
    <collision>
      <origin rpy="0 0 0" xyz="0 0 0"/>
      <geometry>
        <sphere radius="0.036"/>
      </geometry>
    </collision>
    <visual>
      <origin rpy="0 0 0" xyz="0 0 0"/>
      <geometry>
        <sphere radius="0.036"/>
      </geometry>
      <material name="white"/>
    </visual>
    <inertial>
      <origin rpy="0 0 0" xyz="0 0 0"/>
      <mass value="0.1"/>
      <inertia ixx="5.1840000000000005e-05" ixy="0.0" ixz="0.0" iyy="5.1840000000000005e-05" iyz="0.0" izz="5.1840000000000005e-05"/>
    </inertial>
  </link>
  <joint name="caster_rear_wheel_joint" type="fixed">
    <parent link="base_link"/>
    <child link="caster_rear_wheel"/>
    <origin rpy="0 0 0" xyz="-0.219 0 -0.255"/>
  </joint>
  <!-- caster rear wheel Link -->
  <link name="caster_rear_wheel">
    <collision>
      <origin rpy="0 0 0" xyz="0 0 0"/>
      <geometry>
        <sphere radius="0.036"/>
      </geometry>
    </collision>
    <visual>
      <origin rpy="0 0 0" xyz="0 0 0"/>
      <geometry>
        <sphere radius="0.036"/>
      </geometry>
      <material name="white"/>
    </visual>
    <inertial>
      <origin rpy="0 0 0" xyz="0 0 0"/>
      <mass value="0.1"/>
      <inertia ixx="5.1840000000000005e-05" ixy="0.0" ixz="0.0" iyy="5.1840000000000005e-05" iyz="0.0" izz="5.1840000000000005e-05"/>
    </inertial>
  </link>
  <link name="LT_S0_T">
    <visual>
      <geometry>
        <box size="0.015 0.015 1.0 "/>
      </geometry>
      <material name="black"/>
    </visual>
    <collision>
      <geometry>
        <box size="0.015 0.015 1.0 "/>
      </geometry>
    </collision>
  </link>
  <joint name="LT_J_S0_BASE_TO_T" type="fixed">
    <parent link="base_link"/>
    <child link="LT_S0_T"/>
    <origin rpy="0 0 1.5707963267948966" xyz="-0.215 0.255 0.255"/>
  </joint>
  <link name="L_S0_SL">
    <visual>
      <geometry>
        <box size="0.04 0.01 0.131"/>
      </geometry>
      <material name="green"/>
    </visual>
    <collision>
      <geometry>
        <box size="0.04 0.01 0.131"/>
      </geometry>
    </collision>
  </link>
  <joint name="LT_J_S0_T_TO_SL" type="prismatic">
    <parent link="LT_S0_T"/>
    <child link="L_S0_SL"/>
    <origin rpy="0 0 0" xyz="0 0.015 0"/>
    <axis xyz="0 0 1"/>
    <limit effort="1" lower="-0.5" upper="0.5" velocity="1.0"/>
  </joint>
  <link name="L_S1_T">
    <visual>
      <geometry>
        <box size="0.015  0.015 1.2"/>
      </geometry>
      <material name="red"/>
    </visual>
    <collision>
      <geometry>
        <box size="0.015  0.015 1.2"/>
      </geometry>
    </collision>
  </link>
  <joint name="LT_J_S0_SL_TO_S1_T" type="fixed">
    <parent link="L_S0_SL"/>
    <child link="L_S1_T"/>
    <origin rpy="0 0 0" xyz="0 0.01 0.5345"/>
  </joint>
  <link name="L_S1_U_SL">
    <visual>
      <geometry>
        <box size="0.06 0.007 0.131"/>
      </geometry>
      <material name="orange"/>
    </visual>
    <collision>
      <geometry>
        <box size="0.06 0.007 0.131"/>
      </geometry>
    </collision>
  </link>
  <joint name="LT_J_S1_T_TO_U_SL" type="prismatic">
    <parent link="L_S1_T"/>
    <child link="L_S1_U_SL"/>
    <origin rpy="0 0 0" xyz="0 0.0075 0"/>
    <axis xyz="0 0 1"/>
    <limit effort="1" lower="-0.6" upper="0.6" velocity="1.0"/>
  </joint>
  <link name="L_S1_SL_B0">
    <visual>
      <geometry>
        <box size="0.06 0.075 0.0035"/>
      </geometry>
      <material name="orange"/>
    </visual>
    <collision>
      <geometry>
        <box size="0.06 0.075 0.0035"/>
      </geometry>
    </collision>
  </link>
  <link name="L_S1_SL_B1">
    <visual>
      <geometry>
        <box size="0.06 0.075 0.0035"/>
      </geometry>
      <material name="green"/>
    </visual>
    <collision>
      <geometry>
        <box size="0.06 0.075 0.0035"/>
      </geometry>
    </collision>
  </link>
  <joint name="LT_J_S1_SL_TO_B0" type="fixed">
    <parent link="L_S1_U_SL"/>
    <child link="L_S1_SL_B0"/>
    <origin rpy="0 0 0" xyz="0 0.0375  0.0165"/>
  </joint>
  <joint name="LT_J_S1_SL_TO_B1" type="fixed">
    <parent link="L_S1_U_SL"/>
    <child link="L_S1_SL_B1"/>
    <origin rpy="0 0 0" xyz="0 0.0375 -0.0165 "/>
  </joint>
  <link name="L_S1_U_A_L0">
    <visual>
      <geometry>
        <box size="0.23 0.0475 0.025"/>
      </geometry>
      <origin rpy="0 0 0" xyz="0.10 0  0"/>
      <material name="black"/>
    </visual>
    <collision>
      <geometry>
        <box size="0.23 0.0475 0.025"/>
      </geometry>
      <origin rpy="0 0 0" xyz="0.10 0  0"/>
    </collision>
  </link>
  <joint name="LA_J_S1_U_SL_TO_A_L0" type="revolute">
    <parent link="L_S1_SL_B1"/>
    <child link="L_S1_U_A_L0"/>
    <origin rpy="0 0 1.5707963267948966" xyz="0 0.007  0.0165"/>
    <axis xyz="0 0 1"/>
    <limit effort="1" lower="-1.9207963267948966" upper="1.9207963267948966" velocity="1.0"/>
  </joint>
  <link name="L_S1_U_A_L1">
    <visual>
      <geometry>
        <box size="0.23 0.0475 0.025"/>
      </geometry>
      <origin rpy="0 0 0" xyz="0.10 0  0"/>
      <material name="red"/>
    </visual>
    <collision>
      <geometry>
        <box size="0.23 0.0475 0.025"/>
      </geometry>
      <origin rpy="0 0 0" xyz="0.10 0  0"/>
    </collision>
  </link>
  <joint name="LA_J_S1_U_A_L0_TO_L1" type="revolute">
    <parent link="L_S1_U_A_L0"/>
    <child link="L_S1_U_A_L1"/>
    <axis xyz="0 0 1"/>
    <origin rpy="0 0 0" xyz=" 0.20500000000000002 0 0.025"/>
    <limit effort="1" lower="-1.9207963267948966" upper="1.9207963267948966" velocity="1.0"/>
  </joint>
  <link name="L_S1_U_A_L2">
    <visual>
      <geometry>
        <box size="0.005 0.05 0.05"/>
      </geometry>
      <material name="white"/>
    </visual>
    <collision>
      <geometry>
        <box size="0.005 0.05 0.05"/>
      </geometry>
    </collision>
  </link>
  <link name="L_S1_U_A_L2_B0">
    <visual>
      <geometry>
        <box size="0.075 0.06 0.0035"/>
      </geometry>
      <material name="orange"/>
    </visual>
    <collision>
      <geometry>
        <box size="0.075 0.06 0.0035"/>
      </geometry>
    </collision>
  </link>
  <link name="L_S1_U_A_L2_B1">
    <visual>
      <geometry>
        <box size="0.075 0.06 0.0035"/>
      </geometry>
      <material name="white"/>
    </visual>
    <collision>
      <geometry>
        <box size="0.075 0.06 0.0035"/>
      </geometry>
    </collision>
  </link>
  <joint name="LA_J_L_S1_U_A_L2_B0" type="fixed">
    <parent link="L_S1_U_A_L2"/>
    <child link="L_S1_U_A_L2_B0"/>
    <origin rpy="0 0 0" xyz="-0.0375 0  0.016"/>
  </joint>
  <joint name="LA_J_L_S1_U_A_L2_B1" type="fixed">
    <parent link="L_S1_U_A_L2_B1"/>
    <child link="L_S1_U_A_L2"/>
    <origin rpy="0 0 0" xyz="0.0375 0 0.0125 "/>
  </joint>
  <joint name="LA_J_S1_U_A_L1_TO_L2_B1" type="revolute">
    <parent link="L_S1_U_A_L1"/>
    <child link="L_S1_U_A_L2_B1"/>
    <origin rpy="0 0 0" xyz="0.21000000000000002 0 -0.016"/>
    <axis xyz=" 0 0 1"/>
    <limit effort="1" lower="-1.5707963267948966" upper="1.5707963267948966" velocity="1.0"/>
  </joint>
  <link name="RT_S0_T">
    <visual>
      <geometry>
        <box size="0.015 0.015 1.0 "/>
      </geometry>
      <material name="black"/>
    </visual>
    <collision>
      <geometry>
        <box size="0.015 0.015 1.0 "/>
      </geometry>
    </collision>
  </link>
  <joint name="RT_J_S0_BASE_TO_T" type="fixed">
    <parent link="base_link"/>
    <child link="RT_S0_T"/>
    <origin rpy="0 0 1.5707963267948966" xyz="-0.215 -0.255 -0.255"/>
  </joint>
  <link name="R_S0_SL">
    <visual>
      <geometry>
        <box size="0.04 0.01 0.131"/>
      </geometry>
      <material name="green"/>
    </visual>
    <collision>
      <geometry>
        <box size="0.04 0.01 0.131"/>
      </geometry>
    </collision>
  </link>
  <joint name="RT_J_S0_T_TO_SL" type="prismatic">
    <parent link="RT_S0_T"/>
    <child link="R_S0_SL"/>
    <origin rpy="0 0 0" xyz="0 0.015 0"/>
    <axis xyz="0 0 1"/>
    <limit effort="1" lower="-0.5" upper="0.5" velocity="1.0"/>
  </joint>
  <link name="R_S1_T">
    <visual>
      <geometry>
        <box size="0.015  0.015 1.2"/>
      </geometry>
      <material name="red"/>
    </visual>
    <collision>
      <geometry>
        <box size="0.015  0.015 1.2"/>
      </geometry>
    </collision>
  </link>
  <joint name="RT_J_S0_SR_TO_S1_T" type="fixed">
    <parent link="R_S0_SL"/>
    <child link="R_S1_T"/>
    <origin rpy="0 0 0" xyz="0 0.01 0.5345"/>
  </joint>
  <link name="R_S1_U_SL">
    <visual>
      <geometry>
        <box size="0.06 0.007 0.131"/>
      </geometry>
      <material name="orange"/>
    </visual>
    <collision>
      <geometry>
        <box size="0.06 0.007 0.131"/>
      </geometry>
    </collision>
  </link>
  <joint name="RT_J_S1_T_TO_U_SL" type="prismatic">
    <parent link="R_S1_T"/>
    <child link="R_S1_U_SL"/>
    <origin rpy="0 0 0" xyz="0 0.0075 0"/>
    <axis xyz="0 0 1"/>
    <limit effort="1" lower="-0.6" upper="0.6" velocity="1.0"/>
  </joint>
  <link name="R_S1_SR_B0">
    <visual>
      <geometry>
        <box size="0.06 0.075 0.0035"/>
      </geometry>
      <material name="orange"/>
    </visual>
    <collision>
      <geometry>
        <box size="0.06 0.075 0.0035"/>
      </geometry>
    </collision>
  </link>
  <link name="R_S1_SR_B1">
    <visual>
      <geometry>
        <box size="0.06 0.075 0.0035"/>
      </geometry>
      <material name="green"/>
    </visual>
    <collision>
      <geometry>
        <box size="0.06 0.075 0.0035"/>
      </geometry>
    </collision>
  </link>
  <joint name="RT_J_S1_SR_TO_B0" type="fixed">
    <parent link="R_S1_U_SL"/>
    <child link="R_S1_SR_B0"/>
    <origin rpy="0 0 0" xyz="0 0.0375  0.0165"/>
  </joint>
  <joint name="RT_J_S1_SR_TO_B1" type="fixed">
    <parent link="R_S1_U_SL"/>
    <child link="R_S1_SR_B1"/>
    <origin rpy="0 0 0" xyz="0 0.0375 -0.0165 "/>
  </joint>
  <link name="R_S1_U_A_L0">
    <visual>
      <geometry>
        <box size="0.23 0.0475 0.025"/>
      </geometry>
      <origin rpy="0 0 0" xyz="0.10 0  0"/>
      <material name="black"/>
    </visual>
    <collision>
      <geometry>
        <box size="0.23 0.0475 0.025"/>
      </geometry>
      <origin rpy="0 0 0" xyz="0.10 0  0"/>
    </collision>
  </link>
  <joint name="RA_J_S1_U_SR_TO_A_L0" type="revolute">
    <parent link="R_S1_SR_B1"/>
    <child link="R_S1_U_A_L0"/>
    <origin rpy="0 0 1.5707963267948966" xyz="0 0.007  0.0165"/>
    <axis xyz="0 0 1"/>
    <limit effort="1" lower="-1.9207963267948966" upper="1.9207963267948966" velocity="1.0"/>
  </joint>
  <link name="R_S1_U_A_L1">
    <visual>
      <geometry>
        <box size="0.23 0.0475 0.025"/>
      </geometry>
      <origin rpy="0 0 0" xyz="0.10 0  0"/>
      <material name="red"/>
    </visual>
    <collision>
      <geometry>
        <box size="0.23 0.0475 0.025"/>
      </geometry>
      <origin rpy="0 0 0" xyz="0.10 0  0"/>
    </collision>
  </link>
  <joint name="RA_J_S1_U_A_L0_TO_L1" type="revolute">
    <parent link="R_S1_U_A_L0"/>
    <child link="R_S1_U_A_L1"/>
    <axis xyz="0 0 1"/>
    <origin rpy="0 0 0" xyz=" 0.20500000000000002 0 0.025"/>
    <limit effort="1" lower="-1.9207963267948966" upper="1.9207963267948966" velocity="1.0"/>
  </joint>
  <link name="R_S1_U_A_L2">
    <visual>
      <geometry>
        <box size="0.005 0.05 0.05"/>
      </geometry>
      <material name="white"/>
    </visual>
    <collision>
      <geometry>
        <box size="0.005 0.05 0.05"/>
      </geometry>
    </collision>
  </link>
  <link name="R_S1_U_A_L2_B0">
    <visual>
      <geometry>
        <box size="0.075 0.06 0.0035"/>
      </geometry>
      <material name="orange"/>
    </visual>
    <collision>
      <geometry>
        <box size="0.075 0.06 0.0035"/>
      </geometry>
    </collision>
  </link>
  <link name="R_S1_U_A_L2_B1">
    <visual>
      <geometry>
        <box size="0.075 0.06 0.0035"/>
      </geometry>
      <material name="white"/>
    </visual>
    <collision>
      <geometry>
        <box size="0.075 0.06 0.0035"/>
      </geometry>
    </collision>
  </link>
  <joint name="RA_J_R_S1_U_A_L2_B0" type="fixed">
    <parent link="R_S1_U_A_L2"/>
    <child link="R_S1_U_A_L2_B0"/>
    <origin rpy="0 0 0" xyz="-0.0375 0  0.016"/>
  </joint>
  <joint name="RA_J_R_S1_U_A_L2_B1" type="fixed">
    <parent link="R_S1_U_A_L2_B1"/>
    <child link="R_S1_U_A_L2"/>
    <origin rpy="0 0 0" xyz="0.0375 0 0.0125 "/>
  </joint>
  <joint name="RA_J_S1_U_A_L1_TO_L2_B1" type="revolute">
    <parent link="R_S1_U_A_L1"/>
    <child link="R_S1_U_A_L2_B1"/>
    <origin rpy="0 0 0" xyz="0.21000000000000002 0 -0.016"/>
    <axis xyz=" 0 0 1"/>
    <limit effort="1" lower="-1.5707963267948966" upper="1.5707963267948966" velocity="1.0"/>
  </joint>
  <ros2_control name="cobo" type="system">
    <hardware>
      <plugin>cobo_arm_control/RobotSystem</plugin>
    </hardware>
    <param name="LeftTowerPort">ttyACM1</param>
    <param name="RightTowerPort">ttyACM2 </param>
    <param name="LeftArmPort">ttyACM3 </param>
    <param name="RightArmPort">ttyACM4 </param>
    <joint name="RT_J_S0_T_TO_SL">
      <command_interface name="position">
        <param name="min">0</param>
        <param name="max">0.9</param>
      </command_interface>
      <state_interface name="position">
        <param name="initial_value">0.0</param>
      </state_interface>
      <state_interface name="position"/>
    </joint>
    <joint name="RT_J_S1_T_TO_U_SL">
      <command_interface name="position">
        <param name="min">0</param>
        <param name="max">0.9</param>
      </command_interface>
      <state_interface name="position">
        <param name="initial_value">0.0</param>
      </state_interface>
      <state_interface name="position"/>
    </joint>
    <joint name="RA_J_S1_U_SR_TO_A_L0">
      <command_interface name="position">
        <param name="min">-1.5707963267948966</param>
        <param name="max">1.5707963267948966</param>
      </command_interface>
      <state_interface name="position">
        <param name="initial_value">0.0</param>
      </state_interface>
      <state_interface name="position"/>
    </joint>
    <joint name="RA_J_S1_U_A_L0_TO_L1">
      <command_interface name="position">
        <param name="min">-1.5707963267948966</param>
        <param name="max">1.5707963267948966</param>
      </command_interface>
      <state_interface name="position">
        <param name="initial_value">0.0</param>
      </state_interface>
      <state_interface name="position"/>
    </joint>
    <joint name="RA_J_S1_U_A_L1_TO_L2_B1">
      <command_interface name="position">
        <param name="min">-1.5707963267948966</param>
        <param name="max">1.5707963267948966</param>
      </command_interface>
      <state_interface name="position">
        <param name="initial_value">0.0</param>
      </state_interface>
      <state_interface name="position"/>
    </joint>
    <joint name="lT_J_S0_T_TO_SL">
      <command_interface name="position">
        <param name="min">0</param>
        <param name="max">0.9</param>
      </command_interface>
      <state_interface name="position">
        <param name="initial_value">0.0</param>
      </state_interface>
      <state_interface name="position"/>
    </joint>
    <joint name="LT_J_S1_T_TO_U_SL">
      <command_interface name="position">
        <param name="min">0</param>
        <param name="max">0.9</param>
      </command_interface>
      <state_interface name="position">
        <param name="initial_value">0.0</param>
      </state_interface>
      <state_interface name="position"/>
    </joint>
    <joint name="LA_J_S1_U_SR_TO_A_L0">
      <command_interface name="position">
        <param name="min">-1.5707963267948966</param>
        <param name="max">1.5707963267948966</param>
      </command_interface>
      <state_interface name="position">
        <param name="initial_value">0.0</param>
      </state_interface>
      <state_interface name="position"/>
    </joint>
    <joint name="LA_J_S1_U_A_L0_TO_L1">
      <command_interface name="position">
        <param name="min">-1.5707963267948966</param>
        <param name="max">1.5707963267948966</param>
      </command_interface>
      <state_interface name="position">
        <param name="initial_value">0.0</param>
      </state_interface>
      <state_interface name="position"/>
    </joint>
    <joint name="LA_J_S1_U_A_L1_TO_L2_B1">
      <command_interface name="position">
        <param name="min">-1.5707963267948966</param>
        <param name="max">1.5707963267948966</param>
      </command_interface>
      <state_interface name="position">
        <param name="initial_value">0.0</param>
      </state_interface>
      <state_interface name="position"/>
    </joint>
  </ros2_control>
</robot>
