<sdf version='1.7'>
  <model name='diffdrive_robot'>
    <link name='dummy'>
      <inertial>
        <pose>0 0 -0.000421 0 -0 0</pose>
        <mass>45.4</mass>
        <inertia>
          <ixx>1.8895</ixx>
          <ixy>-0.131167</ixy>
          <ixz>0</ixz>
          <iyy>1.76944</iyy>
          <iyz>0</iyz>
          <izz>1.70237</izz>
        </inertia>
      </inertial>
      <collision name='dummy_fixed_joint_lump__base_link_collision'>
        <pose>0 0 0 0 -0 1</pose>
        <geometry>
          <box>
            <size>0.51 0.43 0.51</size>
          </box>
        </geometry>
      </collision>
      <collision name='dummy_fixed_joint_lump__caster_left_frontal_wheel_collision_1'>
        <pose>-0.028236 0.270664 -0.047813 0 -0 1</pose>
        <geometry>
          <sphere>
            <radius>0.0425</radius>
          </sphere>
        </geometry>
      </collision>
      <collision name='dummy_fixed_joint_lump__caster_left_rear_wheel_collision_2'>
        <pose>-0.257864 -0.086961 -0.047813 0 -0 1</pose>
        <geometry>
          <sphere>
            <radius>0.0425</radius>
          </sphere>
        </geometry>
      </collision>
      <collision name='dummy_fixed_joint_lump__caster_right_frontal_wheel_collision_3'>
        <pose>0.257864 0.086961 -0.047813 0 -0 1</pose>
        <geometry>
          <sphere>
            <radius>0.0425</radius>
          </sphere>
        </geometry>
      </collision>
      <collision name='dummy_fixed_joint_lump__caster_right_rear_wheel_collision_4'>
        <pose>0.028236 -0.270664 -0.047813 0 -0 1</pose>
        <geometry>
          <sphere>
            <radius>0.0425</radius>
          </sphere>
        </geometry>
      </collision>
      <visual name='dummy_fixed_joint_lump__base_link_visual'>
        <pose>0 0 0.255 0 -0 1</pose>
        <geometry>
          <box>
            <size>0.51 0.43 0.51</size>
          </box>
        </geometry>
      </visual>
      <visual name='dummy_fixed_joint_lump__caster_left_frontal_wheel_visual_1'>
        <pose>-0.028236 0.270664 -0.047813 0 -0 1</pose>
        <geometry>
          <sphere>
            <radius>0.0425</radius>
          </sphere>
        </geometry>
      </visual>
      <visual name='dummy_fixed_joint_lump__caster_left_rear_wheel_visual_2'>
        <pose>-0.257864 -0.086961 -0.047813 0 -0 1</pose>
        <geometry>
          <sphere>
            <radius>0.0425</radius>
          </sphere>
        </geometry>
      </visual>
      <visual name='dummy_fixed_joint_lump__caster_right_frontal_wheel_visual_3'>
        <pose>0.257864 0.086961 -0.047813 0 -0 1</pose>
        <geometry>
          <sphere>
            <radius>0.0425</radius>
          </sphere>
        </geometry>
      </visual>
      <visual name='dummy_fixed_joint_lump__caster_right_rear_wheel_visual_4'>
        <pose>0.028236 -0.270664 -0.047813 0 -0 1</pose>
        <geometry>
          <sphere>
            <radius>0.0425</radius>
          </sphere>
        </geometry>
      </visual>
    </link>
    <joint name='left_wheel_joint' type='revolute'>
      <pose relative_to='dummy'>0.164087 -0.105359 -0.02125 0 -0 1</pose>
      <parent>dummy</parent>
      <child>left_wheel</child>
      <axis>
        <xyz>0 1 0</xyz>
        <limit>
          <lower>-1e+16</lower>
          <upper>1e+16</upper>
        </limit>
        <dynamics>
          <damping>0.2</damping>
          <friction>0</friction>
          <spring_reference>0</spring_reference>
          <spring_stiffness>0</spring_stiffness>
        </dynamics>
      </axis>
    </joint>
    <link name='left_wheel'>
      <pose relative_to='left_wheel_joint'>0 0 0 0 -0 0</pose>
      <inertial>
        <pose>0 0 0 1.5708 -0 0</pose>
        <mass>3</mass>
        <inertia>
          <ixx>0.055</ixx>
          <ixy>0</ixy>
          <ixz>0</ixz>
          <iyy>0.055</iyy>
          <iyz>0</iyz>
          <izz>0.108</izz>
        </inertia>
      </inertial>
      <collision name='left_wheel_collision'>
        <pose>0 0 0 1.5708 -0 0</pose>
        <geometry>
          <cylinder>
            <length>0.06</length>
            <radius>0.085</radius>
          </cylinder>
        </geometry>
      </collision>
      <visual name='left_wheel_visual'>
        <pose>0 0 0 1.5708 -0 0</pose>
        <geometry>
          <cylinder>
            <length>0.06</length>
            <radius>0.085</radius>
          </cylinder>
        </geometry>
      </visual>
    </link>
    <joint name='right_wheel_joint' type='revolute'>
      <pose relative_to='dummy'>-0.164087 0.105359 -0.02125 0 -0 1</pose>
      <parent>dummy</parent>
      <child>right_wheel</child>
      <axis>
        <xyz>0 1 0</xyz>
        <limit>
          <lower>-1e+16</lower>
          <upper>1e+16</upper>
        </limit>
        <dynamics>
          <damping>0.2</damping>
          <friction>0</friction>
          <spring_reference>0</spring_reference>
          <spring_stiffness>0</spring_stiffness>
        </dynamics>
      </axis>
    </joint>
    <link name='right_wheel'>
      <pose relative_to='right_wheel_joint'>0 0 0 0 -0 0</pose>
      <inertial>
        <pose>0 0 0 1.5708 -0 0</pose>
        <mass>3</mass>
        <inertia>
          <ixx>0.055</ixx>
          <ixy>0</ixy>
          <ixz>0</ixz>
          <iyy>0.055</iyy>
          <iyz>0</iyz>
          <izz>0.108</izz>
        </inertia>
      </inertial>
      <collision name='right_wheel_collision'>
        <pose>0 0 0 1.5708 -0 0</pose>
        <geometry>
          <cylinder>
            <length>0.06</length>
            <radius>0.085</radius>
          </cylinder>
        </geometry>
      </collision>
      <visual name='right_wheel_visual'>
        <pose>0 0 0 1.5708 -0 0</pose>
        <geometry>
          <cylinder>
            <length>0.06</length>
            <radius>0.085</radius>
          </cylinder>
        </geometry>
      </visual>
    </link>
    <static>0</static>
    <plugin name='basic_mobile_bot_diff_drive' filename='libgazebo_ros_diff_drive.so'>
      <update_rate>30</update_rate>
      <left_joint>left_wheel_joint</left_joint>
      <right_joint>right_wheel_joint</right_joint>
      <wheel_separation>0.52</wheel_separation>
      <wheel_diameter>0.17</wheel_diameter>
      <max_wheel_torque>20</max_wheel_torque>
      <max_wheel_acceleration>1.0</max_wheel_acceleration>
      <command_topic>cmd_vel</command_topic>
      <publish_odom>1</publish_odom>
      <publish_odom_tf>0</publish_odom_tf>
      <publish_wheel_tf>0</publish_wheel_tf>
      <odometry_topic>odom</odometry_topic>
      <odometry_frame>odom</odometry_frame>
      <robot_base_frame>base_footprint</robot_base_frame>
      <odometry_source>1</odometry_source>
      <ros>
        <remapping>odom:=wheel/odometry</remapping>
      </ros>
    </plugin>
    <plugin name='basic_mobile_bot_joint_state' filename='libgazebo_ros_joint_state_publisher.so'>
      <ros>
        <remapping>~/out:=joint_states</remapping>
      </ros>
      <update_rate>30</update_rate>
      <joint_name>left_wheel_joint</joint_name>
      <joint_name>right_wheel_joint</joint_name>
    </plugin>
  </model>
</sdf>
