<?xml version="1.0" ?>
<!-- =================================================================================== -->
<!-- |    This document was autogenerated by xacro from diffbot.urdf.xacro             | -->
<!-- |    EDITING THIS FILE BY HAND IS NOT RECOMMENDED                                 | -->
<!-- =================================================================================== -->
<!-- Basic differential drive mobile base -->
<robot name="diffdrive_robot">
  <material name="black">
    <color rgba="0.0 0.0 0.0 1.0"/>
  </material>
  <material name="blue">
    <color rgba="0.0 0.0 0.8 1.0"/>
  </material>
  <material name="green">
    <color rgba="0.0 0.8 0.0 1.0"/>
  </material>
  <material name="grey">
    <color rgba="0.2 0.2 0.2 1.0"/>
  </material>
  <material name="orange">
    <color rgba="1.0 0.4235294117647059 0.0392156862745098 1.0"/>
  </material>
  <material name="brown">
    <color rgba="0.8705882352941177 0.8117647058823529 0.7647058823529411 1.0"/>
  </material>
  <material name="red">
    <color rgba="0.8 0.0 0.0 1.0"/>
  </material>
  <material name="white">
    <color rgba="1.0 1.0 1.0 1.0"/>
  </material>
  <!-- Space btw top of beam and the each joint -->
  <link name="dummy"/>
  <joint name="dummy_joint" type="fixed">
    <parent link="dummy"/>
    <child link="base_link"/>
  </joint>
  <!-- Base Link -->
  <link name="base_link">
    <collision>
      <origin rpy="0 0 0" xyz="0 0 0"/>
      <geometry>
        <box size="0.51 0.43 0.51"/>
      </geometry>
    </collision>
    <visual>
      <origin rpy="0 0 0" xyz="0 0 0.255"/>
      <geometry>
        <box size="0.51 0.43 0.51"/>
      </geometry>
      <material name="orange"/>
    </visual>
    <inertial>
      <origin rpy="0 0 0" xyz="0 0 0"/>
      <mass value="45"/>
      <inertia ixx="1.6687499999999997" ixy="0.0" ixz="0.0" iyy="1.95075" iyz="0.0" izz="1.6687499999999997"/>
    </inertial>
  </link>
  <joint name="left_wheel_joint" type="continuous">
    <parent link="base_link"/>
    <child link="left_wheel"/>
    <origin rpy="0 0 0" xyz="0 -0.195 -0.02125"/>
    <axis xyz="0 1 0"/>
    <dynamics damping="0.2"/>
  </joint>
  <!-- left wheel Link -->
  <link name="left_wheel">
    <collision>
      <origin rpy="1.5707963267948966 0 0" xyz="0 0 0"/>
      <geometry>
        <cylinder length="0.06" radius="0.085"/>
      </geometry>
    </collision>
    <visual>
      <origin rpy="1.5707963267948966 0 0" xyz="0 0 0"/>
      <geometry>
        <cylinder length="0.06" radius="0.085"/>
      </geometry>
      <material name="black"/>
    </visual>
    <inertial>
      <origin rpy="1.5707963267948966 0 0" xyz="0 0 0"/>
      <mass value="3.0"/>
      <inertia ixx="0.055" ixy="0.0" ixz="0.0" iyy="0.055" iyz="0.0" izz="0.108"/>
    </inertial>
  </link>
  <joint name="right_wheel_joint" type="continuous">
    <parent link="base_link"/>
    <child link="right_wheel"/>
    <origin rpy="0 0 0" xyz="0 0.195 -0.02125"/>
    <axis xyz="0 1 0"/>
    <dynamics damping="0.2"/>
  </joint>
  <!-- right wheel Link -->
  <link name="right_wheel">
    <collision>
      <origin rpy="1.5707963267948966 0 0" xyz="0 0 0"/>
      <geometry>
        <cylinder length="0.06" radius="0.085"/>
      </geometry>
    </collision>
    <visual>
      <origin rpy="1.5707963267948966 0 0" xyz="0 0 0"/>
      <geometry>
        <cylinder length="0.06" radius="0.085"/>
      </geometry>
      <material name="black"/>
    </visual>
    <inertial>
      <origin rpy="1.5707963267948966 0 0" xyz="0 0 0"/>
      <mass value="3.0"/>
      <inertia ixx="0.055" ixy="0.0" ixz="0.0" iyy="0.055" iyz="0.0" izz="0.108"/>
    </inertial>
  </link>
  <joint name="caster_left_frontal_wheel_joint" type="fixed">
    <parent link="base_link"/>
    <child link="caster_left_frontal_wheel"/>
    <origin rpy="0 0 0" xyz="0.2125 0.16999999999999998 -0.0478125"/>
  </joint>
  <!-- caster left frontal wheel Link -->
  <link name="caster_left_frontal_wheel">
    <collision>
      <origin rpy="0 0 0" xyz="0 0 0"/>
      <geometry>
        <sphere radius="0.0425"/>
      </geometry>
    </collision>
    <visual>
      <origin rpy="0 0 0" xyz="0 0 0"/>
      <geometry>
        <sphere radius="0.0425"/>
      </geometry>
      <material name="white"/>
    </visual>
    <inertial>
      <origin rpy="0 0 0" xyz="0 0 0"/>
      <mass value="0.1"/>
      <inertia ixx="0.001" ixy="0.0" ixz="0.0" iyy="0.001" iyz="0.0" izz="0.001"/>
    </inertial>
  </link>
  <joint name="caster_right_frontal_wheel_joint" type="fixed">
    <parent link="base_link"/>
    <child link="caster_right_frontal_wheel"/>
    <origin rpy="0 0 0" xyz="0.2125 -0.16999999999999998 -0.0478125"/>
  </joint>
  <!-- caster right frontal wheel Link -->
  <link name="caster_right_frontal_wheel">
    <collision>
      <origin rpy="0 0 0" xyz="0 0 0"/>
      <geometry>
        <sphere radius="0.0425"/>
      </geometry>
    </collision>
    <visual>
      <origin rpy="0 0 0" xyz="0 0 0"/>
      <geometry>
        <sphere radius="0.0425"/>
      </geometry>
      <material name="white"/>
    </visual>
    <inertial>
      <origin rpy="0 0 0" xyz="0 0 0"/>
      <mass value="0.1"/>
      <inertia ixx="0.001" ixy="0.0" ixz="0.0" iyy="0.001" iyz="0.0" izz="0.001"/>
    </inertial>
  </link>
  <joint name="caster_left_rear_wheel_joint" type="fixed">
    <parent link="base_link"/>
    <child link="caster_left_rear_wheel"/>
    <origin rpy="0 0 0" xyz="-0.2125 0.16999999999999998 -0.0478125"/>
  </joint>
  <!-- caster left rear wheel Link -->
  <link name="caster_left_rear_wheel">
    <collision>
      <origin rpy="0 0 0" xyz="0 0 0"/>
      <geometry>
        <sphere radius="0.0425"/>
      </geometry>
    </collision>
    <visual>
      <origin rpy="0 0 0" xyz="0 0 0"/>
      <geometry>
        <sphere radius="0.0425"/>
      </geometry>
      <material name="white"/>
    </visual>
    <inertial>
      <origin rpy="0 0 0" xyz="0 0 0"/>
      <mass value="0.1"/>
      <inertia ixx="0.001" ixy="0.0" ixz="0.0" iyy="0.001" iyz="0.0" izz="0.001"/>
    </inertial>
  </link>
  <joint name="caster_right_rear_wheel_joint" type="fixed">
    <parent link="base_link"/>
    <child link="caster_right_rear_wheel"/>
    <origin rpy="0 0 0" xyz="-0.2125 -0.16999999999999998 -0.0478125"/>
  </joint>
  <!-- caster right rear wheel Link -->
  <link name="caster_right_rear_wheel">
    <collision>
      <origin rpy="0 0 0" xyz="0 0 0"/>
      <geometry>
        <sphere radius="0.0425"/>
      </geometry>
    </collision>
    <visual>
      <origin rpy="0 0 0" xyz="0 0 0"/>
      <geometry>
        <sphere radius="0.0425"/>
      </geometry>
      <material name="white"/>
    </visual>
    <inertial>
      <origin rpy="0 0 0" xyz="0 0 0"/>
      <mass value="0.1"/>
      <inertia ixx="0.001" ixy="0.0" ixz="0.0" iyy="0.001" iyz="0.0" izz="0.001"/>
    </inertial>
  </link>
  <ros2_control name="DiffBot" type="system">
    <hardware>
      <plugin>diffdrive_arduino/DiffDriveArduinoHardware</plugin>
      <param name="left_wheel_name">left_wheel_joint</param>
      <param name="right_wheel_name">right_wheel_joint</param>
      <param name="loop_rate">2.0</param>
      <param name="device">/dev/ttyACM1</param>
      <param name="baud_rate">57600</param>
      <param name="timeout_ms">1000</param>
      <param name="enc_counts_per_rev">90</param>
      <param name="pid_p">30</param>
      <param name="pid_d">12</param>
      <param name="pid_i">0</param>
      <param name="pid_o">50</param>
    </hardware>
    <joint name="left_wheel_joint">
      <command_interface name="velocity"/>
      <state_interface name="position"/>
      <state_interface name="velocity"/>
    </joint>
    <joint name="right_wheel_joint">
      <command_interface name="velocity"/>
      <state_interface name="position"/>
      <state_interface name="velocity"/>
    </joint>
  </ros2_control>
</robot>
