<sdf version='1.7'>
  <model name='diffdrive_robot'>
    <link name='dummy'>
      <inertial>
        <pose>0 0 -0.000421 0 -0 0</pose>
        <mass>45.4</mass>
        <inertia>
          <ixx>1.68522</ixx>
          <ixy>0</ixy>
          <ixz>0</ixz>
          <iyy>1.97372</iyy>
          <iyz>0</iyz>
          <izz>1.70237</izz>
        </inertia>
      </inertial>
      <collision name='dummy_fixed_joint_lump__base_link_collision'>
        <pose>0 0 0 0 -0 0</pose>
        <geometry>
          <box>
            <size>0.51 0.43 0.51</size>
          </box>
        </geometry>
      </collision>
      <collision name='dummy_fixed_joint_lump__caster_left_frontal_wheel_collision_1'>
        <pose>0.2125 0.17 -0.047813 0 -0 0</pose>
        <geometry>
          <sphere>
            <radius>0.0425</radius>
          </sphere>
        </geometry>
      </collision>
      <collision name='dummy_fixed_joint_lump__caster_left_rear_wheel_collision_2'>
        <pose>-0.2125 0.17 -0.047813 0 -0 0</pose>
        <geometry>
          <sphere>
            <radius>0.0425</radius>
          </sphere>
        </geometry>
      </collision>
      <collision name='dummy_fixed_joint_lump__caster_right_frontal_wheel_collision_3'>
        <pose>0.2125 -0.17 -0.047813 0 -0 0</pose>
        <geometry>
          <sphere>
            <radius>0.0425</radius>
          </sphere>
        </geometry>
      </collision>
      <collision name='dummy_fixed_joint_lump__caster_right_rear_wheel_collision_4'>
        <pose>-0.2125 -0.17 -0.047813 0 -0 0</pose>
        <geometry>
          <sphere>
            <radius>0.0425</radius>
          </sphere>
        </geometry>
      </collision>
      <visual name='dummy_fixed_joint_lump__base_link_visual'>
        <pose>0 0 0.255 0 -0 0</pose>
        <geometry>
          <box>
            <size>0.51 0.43 0.51</size>
          </box>
        </geometry>
      </visual>
      <visual name='dummy_fixed_joint_lump__caster_left_frontal_wheel_visual_1'>
        <pose>0.2125 0.17 -0.047813 0 -0 0</pose>
        <geometry>
          <sphere>
            <radius>0.0425</radius>
          </sphere>
        </geometry>
      </visual>
      <visual name='dummy_fixed_joint_lump__caster_left_rear_wheel_visual_2'>
        <pose>-0.2125 0.17 -0.047813 0 -0 0</pose>
        <geometry>
          <sphere>
            <radius>0.0425</radius>
          </sphere>
        </geometry>
      </visual>
      <visual name='dummy_fixed_joint_lump__caster_right_frontal_wheel_visual_3'>
        <pose>0.2125 -0.17 -0.047813 0 -0 0</pose>
        <geometry>
          <sphere>
            <radius>0.0425</radius>
          </sphere>
        </geometry>
      </visual>
      <visual name='dummy_fixed_joint_lump__caster_right_rear_wheel_visual_4'>
        <pose>-0.2125 -0.17 -0.047813 0 -0 0</pose>
        <geometry>
          <sphere>
            <radius>0.0425</radius>
          </sphere>
        </geometry>
      </visual>
    </link>
    <joint name='left_wheel_joint' type='revolute'>
      <pose relative_to='dummy'>0 -0.195 -0.02125 0 -0 0</pose>
      <parent>dummy</parent>
      <child>left_wheel</child>
      <axis>
        <xyz>0 1 0</xyz>
        <limit>
          <lower>-1e+16</lower>
          <upper>1e+16</upper>
        </limit>
        <dynamics>
          <damping>0.2</damping>
          <friction>0</friction>
          <spring_reference>0</spring_reference>
          <spring_stiffness>0</spring_stiffness>
        </dynamics>
      </axis>
    </joint>
    <link name='left_wheel'>
      <pose relative_to='left_wheel_joint'>0 0 0 0 -0 0</pose>
      <inertial>
        <pose>0 0 0 1.5708 -0 0</pose>
        <mass>3</mass>
        <inertia>
          <ixx>0.055</ixx>
          <ixy>0</ixy>
          <ixz>0</ixz>
          <iyy>0.055</iyy>
          <iyz>0</iyz>
          <izz>0.108</izz>
        </inertia>
      </inertial>
      <collision name='left_wheel_collision'>
        <pose>0 0 0 1.5708 -0 0</pose>
        <geometry>
          <cylinder>
            <length>0.06</length>
            <radius>0.085</radius>
          </cylinder>
        </geometry>
      </collision>
      <visual name='left_wheel_visual'>
        <pose>0 0 0 1.5708 -0 0</pose>
        <geometry>
          <cylinder>
            <length>0.06</length>
            <radius>0.085</radius>
          </cylinder>
        </geometry>
      </visual>
    </link>
    <joint name='right_wheel_joint' type='revolute'>
      <pose relative_to='dummy'>0 0.195 -0.02125 0 -0 0</pose>
      <parent>dummy</parent>
      <child>right_wheel</child>
      <axis>
        <xyz>0 1 0</xyz>
        <limit>
          <lower>-1e+16</lower>
          <upper>1e+16</upper>
        </limit>
        <dynamics>
          <damping>0.2</damping>
          <friction>0</friction>
          <spring_reference>0</spring_reference>
          <spring_stiffness>0</spring_stiffness>
        </dynamics>
      </axis>
    </joint>
    <link name='right_wheel'>
      <pose relative_to='right_wheel_joint'>0 0 0 0 -0 0</pose>
      <inertial>
        <pose>0 0 0 1.5708 -0 0</pose>
        <mass>3</mass>
        <inertia>
          <ixx>0.055</ixx>
          <ixy>0</ixy>
          <ixz>0</ixz>
          <iyy>0.055</iyy>
          <iyz>0</iyz>
          <izz>0.108</izz>
        </inertia>
      </inertial>
      <collision name='right_wheel_collision'>
        <pose>0 0 0 1.5708 -0 0</pose>
        <geometry>
          <cylinder>
            <length>0.06</length>
            <radius>0.085</radius>
          </cylinder>
        </geometry>
      </collision>
      <visual name='right_wheel_visual'>
        <pose>0 0 0 1.5708 -0 0</pose>
        <geometry>
          <cylinder>
            <length>0.06</length>
            <radius>0.085</radius>
          </cylinder>
        </geometry>
      </visual>
    </link>
  </model>
</sdf>
